Workbook

Sheet COVER
B2: MINFin - Model for Informed National Financing
B3: Data Input File
B5: Model Information
B6: Country / Case | C6: Kenya
B7: Prepared by | C7: Hannah Luscombe
B8: Date | C8: 46133
B9: Model version | C9: v2.0.0
B10: Notes
B12: Worksheet navigator - click to go to sheet
B13: → MACROECONOMIC | C13: Inflation, FX, GDP growth, population
B14: → TECHNOLOGY REGISTER | C14: Technology codes, classifications, descriptions
B15: → INVESTMENT PLAN | C15: Capital cost, generation, OPEX & emissions by scenario
B16: → EXISTING INFRASTRUCTURE | C16: Existing financing records
B17: → NEW INFRASTRUCTURE | C17: Interest rates, fees, amortisation
B18: → PPA REVENUE | C18: Contracted generation and PPA cashflow inflows
B19: → WHOLESALE REVENUE | C19: Market-based generation revenue by off-taker
B20: → OTHER REVENUE | C20: Grants, receivables, redispatch compensation
B22: Colour conventions
B23: Blue text | C23: Hardcoded inputs - values you edit

Sheet MACROECONOMIC
B2: MACROECONOMIC PARAMETERS
B3: ← Return to COVER
B5: Parameter | C5: Code | D5: Unit | E5: Time Independent | F5: 2010 | G5: 2011 | H5: 2012 | I5: 2013 | J5: 2014 | K5: 2015 | L5: 2016 | M5: 2017 | N5: 2018 | O5: 2019 | P5: 2020 | Q5: 2021 | R5: 2022 | S5: 2023 | T5: 2024 | U5: 2025 | V5: 2026 | W5: 2027 | X5: 2028 | Y5: 2029 | Z5: 2030 | AA5: 2031 | AB5: 2032 | AC5: 2033 | AD5: 2034 | AE5: 2035 | AF5: 2036 | AG5: 2037 | AH5: 2038 | AI5: 2039 | AJ5: 2040 | AK5: 2041 | AL5: 2042 | AM5: 2043 | AN5: 2044 | AO5: 2045 | AP5: 2046 | AQ5: 2047 | AR5: 2048 | AS5: 2049 | AT5: 2050 | AU5: 2051 | AV5: 2052 | AW5: 2053 | AX5: 2054 | AY5: 2055 | AZ5: 2056 | BA5: 2057 | BB5: 2058 | BC5: 2059 | BD5: 2060 | BE5: 2061 | BF5: 2062 | BG5: 2063 | BH5: 2064 | BI5: 2065 | BJ5: 2066 | BK5: 2067 | BL5: 2068 | BM5: 2069 | BN5: 2070
B6: 1. Exchange Rates
B7: Display Currency | E7: USD
B8: Foreign Currency | C8: USD | D8: LCU/USD | F8: 1 | G8: 1 | H8: 1 | I8: 1 | J8: 1 | K8: 1 | L8: 1 | M8: 1 | N8: 1 | O8: 1 | P8: 1 | Q8: 1 | R8: 1 | S8: 1 | T8: 1 | U8: 1 | V8: 1 | W8: 1 | X8: 1 | Y8: 1 | Z8: 1 | AA8: 1 | AB8: 1 | AC8: 1 | AD8: 1 | AE8: 1 | AF8: 1 | AG8: 1 | AH8: 1 | AI8: 1 | AJ8: 1 | AK8: 1 | AL8: 1 | AM8: 1 | AN8: 1 | AO8: 1 | AP8: 1 | AQ8: 1 | AR8: 1 | AS8: 1 | AT8: 1 | AU8: 1 | AV8: 1 | AW8: 1 | AX8: 1 | AY8: 1 | AZ8: 1 | BA8: 1 | BB8: 1 | BC8: 1 | BD8: 1 | BE8: 1 | BF8: 1 | BG8: 1 | BH8: 1 | BI8: 1 | BJ8: 1 | BK8: 1 | BL8: 1 | BM8: 1 | BN8: 1
B9: Local Currency | C9: KES | D9: LCU/USD | F9: 79.23 | G9: 88.81 | H9: 84.53 | I9: 86.12 | J9: 87.92 | K9: 98.18 | L9: 101.5 | M9: 103.41 | N9: 101.3 | O9: 101.99 | P9: 106.45 | Q9: 109.64 | R9: 117.87 | S9: 139.85 | T9: 134.82 | U9: 134.82 | V9: 138.47362 | W9: 142.22626 | X9: 146.08059 | Y9: 150.03937 | Z9: 154.10544 | AA9: 158.2817 | AB9: 162.57113 | AC9: 166.97681 | AD9: 171.50188 | AE9: 176.14958 | AF9: 180.92323 | AG9: 185.82625 | AH9: 190.86215 | AI9: 196.03451 | AJ9: 201.34705 | AK9: 206.80355 | AL9: 212.40793 | AM9: 218.16418 | AN9: 224.07643 | AO9: 230.1489 | AP9: 236.38594 | AQ9: 242.792 | AR9: 249.37166 | AS9: 256.12963 | AT9: 263.07074 | AU9: 270.19996 | AV9: 277.52238 | AW9: 285.04324 | AX9: 292.76791 | AY9: 300.70192 | AZ9: 308.85094 | BA9: 317.2208 | BB9: 325.81749 | BC9: 334.64714 | BD9: 343.71608 | BE9: 353.03078 | BF9: 362.59792 | BG9: 372.42432 | BH9: 382.51702 | BI9: 392.88323 | BJ9: 403.53037 | BK9: 414.46604 | BL9: 425.69807 | BM9: 437.23449 | BN9: 449.08354
B10: Currency | C10: CNY | D10: LCU/USD
B11: Currency | C11: EUR | D11: LCU/USD
B12: Currency | C12: JPY | D12: LCU/USD
B13: Currency | C13: OT4 | D13: LCU/USD
B14: Currency | C14: OT5 | D14: LCU/USD
B15: Currency | C15: OT6 | D15: LCU/USD
B16: Currency | C16: OT7 | D16: LCU/USD
B17: Currency | C17: OT8 | D17: LCU/USD
B18: 2. Macroeconomic Aggregates
B19: Annual GDP | D19: Mn USD | U19: 75244 | V19: 76019 | W19: 81084 | X19: 86456 | Y19: 92244 | Z19: 98554 | AA19: 103482 | AB19: 108656 | AC19: 114089 | AD19: 119793 | AE19: 125783 | AF19: 132072 | AG19: 138675 | AH19: 145609 | AI19: 152890 | AJ19: 160534 | AK19: 168561 | AL19: 176989 | AM19: 185838 | AN19: 195130 | AO19: 204887 | AP19: 215131 | AQ19: 225888 | AR19: 237182 | AS19: 249041 | AT19: 261493 | AU19: 274568 | AV19: 288296 | AW19: 302711 | AX19: 317846 | AY19: 333739 | AZ19: 350426 | BA19: 367947 | BB19: 386344 | BC19: 405662 | BD19: 425945 | BE19: 447242 | BF19: 469604 | BG19: 493084 | BH19: 517738 | BI19: 543625 | BJ19: 570807 | BK19: 599347 | BL19: 629314 | BM19: 660780 | BN19: 693819
B20: 3. Discount Rates
B21: Discount Rate | D21: % p.a. | E21: 0.089
B22: 4. Annual Loan Repayments
B23: Annual Loan Repayments | E23: 1
B24: 5. Current Year
B25: Current Year | E25: 2026

Sheet TECHNOLOGY REGISTER
B2: TECHNOLOGY REGISTER
B3: ← Return to COVER
B5: Name | C5: Description | D5: Technology | E5: Classification
B6: 1. Financing Technologies
D7: Biomass | E7: Generation Renewable
D8: Geothermal | E8: Generation Renewable
D9: Solar PV | E9: Generation Renewable
D10: CSP | E10: Generation Renewable
D11: Hydropower | E11: Generation Renewable
D12: Nuclear | E12: Generation Renewable
D13: Wind | E13: Generation Renewable
D14: Coal | E14: Generation Fossil-Fuel
D15: Oil | E15: Generation Fossil-Fuel
D16: Gas | E16: Generation Fossil-Fuel
D17: Transmission | E17: Transmission Infrastructure
D18: Distribution | E18: Distribution Infrastructure
... D23: Direct Hydro | E23: Generation Renewable
B57: 2. Investment Plan Technologies
B58: BESS_TECH | C58: Battery | D58: Battery | E58: Generation Renewable
B59: PWRBIO | C59: Biomass | D59: Biomass | E59: Generation Renewable
B60: PWRDIST | C60: Distribution | D60: Distribution | E60: Distribution Infrastructure
B61: PWRGEO | C61: Geothermal | D61: Geothermal | E61: Generation Renewable
B62: PWRHYD | C62: Hydropower | D62: Hydropower | E62: Generation Renewable
B63: PWRNGS | C63: Natural Gas | D63: Gas | E63: Generation Fossil-Fuel
B64: PWRPHS | C64: Pumped Hydro with Storage | D64: Hydropower | E64: Generation Renewable
B65: PWRSOL | C65: Solar PV | D65: Solar PV | E65: Generation Renewable
B66: PWRTRN | C66: Transmission | D66: Transmission | E66: Transmission Infrastructure
B67: PWRWND | C67: Onshore Wind | D67: Wind | E67: Generation Renewable
B68: PWRHFO | C68: Oil | D68: Oil | E68: Generation Fossil-Fuel
B69: PWRIMP | C69: Imports | D69: Imports | E69: Generation Renewable
... B72: PWRHYD16 | C72: Direct Hydro | D72: Hydropower | E72: Generation Renewable

Sheet INVESTMENT PLAN
B1: INVESTMENT PLAN - CAPITAL COST, GENERATION, OPEX & EMISSIONS
B2: ← Return to COVER
B4: Variable | C4: Scenario | D4: Technology | E4: Unit | F4: 2025 | G4: 2026 | H4: 2027 | I4: 2028 | J4: 2029 | K4: 2030 | L4: 2031 | M4: 2032 | N4: 2033 | O4: 2034 | P4: 2035 | Q4: 2036 | R4: 2037 | S4: 2038 | T4: 2039 | U4: 2040 | V4: 2041 | W4: 2042 | X4: 2043 | Y4: 2044 | Z4: 2045 | AA4: 2046 | AB4: 2047 | AC4: 2048 | AD4: 2049 | AE4: 2050 | AF4: 2051 | AG4: 2052 | AH4: 2053 | AI4: 2054 | AJ4: 2055 | AK4: 2056 | AL4: 2057 | AM4: 2058 | AN4: 2059 | AO4: 2060 | AP4: 2061 | AQ4: 2062 | AR4: 2063 | AS4: 2064 | AT4: 2065 | AU4: 2066 | AV4: 2067 | AW4: 2068 | AX4: 2069 | AY4: 2070
B5: 1. Capital Cost
B6: Capital Cost | C6: Net Zero | D6: =IF('TECHNOLOGY REGISTER'!B58="","",'TECHNOLOGY REGISTER'!B58) -> BESS_TECH | E6: Mn USD | F6: 103.2542 | G6: 0 | H6: 0 | I6: 0 | J6: 0 | K6: 0 | L6: 162.2502 | M6: 33.746 | N6: 0 | O6: 0 | P6: 0 | Q6: 0 | R6: 0 | S6: 0 | T6: 81.5446 | U6: 12.7482 | V6: 191.9648 | W6: 15.4089 | X6: 35.162 | Y6: 47.3597 | Z6: 38.9349 | AA6: 55.6084 | AB6: 116.6024 | AC6: 73.1279 | AD6: 138.8401 | AE6: 83.7669 | AF6: 261.3643 | AG6: 125.1638 | AH6: 154.0223 | AI6: 88.224 | AJ6: 97.7081 | AK6: 123.3413 | AL6: 147.6428 | AM6: 114.8274 | AN6: 176.5708 | AO6: 157.1402 | AP6: 317.4706 | AQ6: 173.3126 | AR6: 196.9104 | AS6: 133.1354 | AT6: 138.7752 | AU6: 164.206 | AV6: 188.5075 | AW6: 155.6921 | AX6: 217.4356 | AY6: 198.9484
B7: Capital Cost | C7: Net Zero | D7: =IF('TECHNOLOGY REGISTER'!B59="","",'TECHNOLOGY REGISTER'!B59) -> PWRBIO | E7: Mn USD | F7: 0 | G7: 25 | H7: 0 | I7: 20 | J7: 0 | K7: 120.5 | L7: 50 | M7: 27 | N7: 7.5 | O7: 15 | P7: 0.75 | Q7: 0 | R7: 0 | S7: 0 | T7: 0 | U7: 0 | V7: 0 | W7: 0 | X7: 0 | Y7: 0 | Z7: 0 | AA7: 0 | AB7: 0 | AC7: 0 | AD7: 0 | AE7: 0 | AF7: 0 | AG7: 0 | AH7: 0 | AI7: 0 | AJ7: 0 | AK7: 0 | AL7: 0 | AM7: 0 | AN7: 0 | AO7: 0 | AP7: 0 | AQ7: 0 | AR7: 0 | AS7: 0 | AT7: 0 | AU7: 0 | AV7: 0 | AW7: 0 | AX7: 0 | AY7: 0
B8: Capital Cost | C8: Net Zero | D8: =IF('TECHNOLOGY REGISTER'!B60="","",'TECHNOLOGY REGISTER'!B60) -> PWRDIST | E8: Mn USD | F8: 191.7485 | G8: 168.7515 | H8: 318.4243 | I8: 348.2791 | J8: 393.2781 | K8: 384.609 | L8: 367.281 | M8: 424.6634 | N8: 412.6597 | O8: 451.1339 | P8: 467.8629 | Q8: 480.0965 | R8: 576.4281 | S8: 600.4495 | T8: 634.8718 | U8: 673.1133 | V8: 709.2074 | W8: 734.0224 | X8: 782.8371 | Y8: 824.6059 | Z8: 871.8016 | AA8: 920.0218 | AB8: 969.0675 | AC8: 1024.625 | AD8: 1081.2863 | AE8: 1138.7645 | AF8: 897.2713 | AG8: 897.2713 | AH8: 897.2713 | AI8: 897.2713 | AJ8: 897.2713 | AK8: 897.2713 | AL8: 897.2713 | AM8: 897.2713 | AN8: 897.2713 | AO8: 897.2713 | AP8: 897.2713 | AQ8: 897.2713 | AR8: 897.2713 | AS8: 897.2713 | AT8: 897.2713 | AU8: 897.2713 | AV8: 897.2713 | AW8: 897.2713 | AX8: 897.2713 | AY8: 897.2713
B9: Capital Cost | C9: Net Zero | D9: =IF('TECHNOLOGY REGISTER'!B61="","",'TECHNOLOGY REGISTER'!B61) -> PWRGEO | E9: Mn USD | F9: 278.2473 | G9: 544.2528 | H9: 403.9956 | I9: 331.8354 | J9: 1158.2439 | K9: 217.3667 | L9: 529.4999 | M9: 212.7511 | N9: 163.4556 | O9: 599.6646 | P9: 313.4014 | Q9: 737.8513 | R9: 628.0851 | S9: 561.8408 | T9: 1012.8712 | U9: 1488.0749 | V9: 1011.1725 | W9: 435.8816 | X9: 435.8816 | Y9: 490.3668 | Z9: 544.852 | AA9: 599.3372 | AB9: 653.8224 | AC9: 708.3076 | AD9: 817.278 | AE9: 1007.6455 | AF9: 1089.1048 | AG9: 948.8476 | AH9: 876.6874 | AI9: 1703.0959 | AJ9: 762.2187 | AK9: 1074.3519 | AL9: 757.6031 | AM9: 708.3076 | AN9: 1144.5166 | AO9: 858.2534 | AP9: 1282.7033 | AQ9: 1172.9371 | AR9: 1106.6928 | AS9: 1557.7232 | AT9: 2032.9269 | AU9: 1556.0245 | AV9: 980.7336 | AW9: 980.7336 | AX9: 1035.2188 | AY9: 1089.704
B10: Capital Cost | C10: Net Zero | D10: =IF('TECHNOLOGY REGISTER'!B62="","",'TECHNOLOGY REGISTER'!B62) -> PWRHYD | E10: Mn USD | F10: 0 | G10: 0 | H10: 0 | I10: 0 | J10: 0 | K10: 0 | L10: 0 | M10: 0 | N10: 0 | O10: 0 | P10: 0 | Q10: 0 | R10: 0 | S10: 0 | T10: 0 | U10: 0 | V10: 0 | W10: 0 | X10: 0 | Y10: 0 | Z10: 0 | AA10: 0 | AB10: 0 | AC10: 0 | AD10: 0 | AE10: 0 | AF10: 0 | AG10: 0 | AH10: 0 | AI10: 0 | AJ10: 0 | AK10: 0 | AL10: 0 | AM10: 0 | AN10: 0 | AO10: 0 | AP10: 0 | AQ10: 0 | AR10: 0 | AS10: 0 | AT10: 0 | AU10: 0 | AV10: 0 | AW10: 0 | AX10: 0 | AY10: 0
B11: Capital Cost | C11: Net Zero | D11: =IF('TECHNOLOGY REGISTER'!B63="","",'TECHNOLOGY REGISTER'!B63) -> PWRNGS | E11: Mn USD | F11: 0 | G11: 0 | H11: 83.0037 | I11: 19.8531 | J11: 0 | K11: 58.2855 | L11: 0 | M11: 0 | N11: 0 | O11: 0 | P11: 0 | Q11: 0 | R11: 0 | S11: 0 | T11: 0 | U11: 0 | V11: 0 | W11: 0 | X11: 0 | Y11: 0 | Z11: 0 | AA11: 0 | AB11: 0 | AC11: 0 | AD11: 0 | AE11: 0 | AF11: 0 | AG11: 0 | AH11: 0 | AI11: 0 | AJ11: 0 | AK11: 0 | AL11: 0 | AM11: 0 | AN11: 0 | AO11: 0 | AP11: 0 | AQ11: 0 | AR11: 0 | AS11: 0 | AT11: 0 | AU11: 0 | AV11: 0 | AW11: 0 | AX11: 0 | AY11: 0
B12: Capital Cost | C12: Net Zero | D12: =IF('TECHNOLOGY REGISTER'!B64="","",'TECHNOLOGY REGISTER'!B64) -> PWRPHS | E12: Mn USD | F12: 0 | G12: 0 | H12: 0 | I12: 0 | J12: 0 | K12: 0 | L12: 0 | M12: 0 | N12: 0 | O12: 251.2396 | P12: 211.9784 | Q12: 141.1703 | R12: 79.2868 | S12: 0 | T12: 0 | U12: 0 | V12: 0 | W12: 0 | X12: 0 | Y12: 0 | Z12: 0 | AA12: 0 | AB12: 0 | AC12: 0 | AD12: 0 | AE12: 0 | AF12: 0 | AG12: 0 | AH12: 0 | AI12: 0 | AJ12: 0 | AK12: 0 | AL12: 0 | AM12: 0 | AN12: 0 | AO12: 0 | AP12: 0 | AQ12: 0 | AR12: 0 | AS12: 0 | AT12: 0 | AU12: 0 | AV12: 0 | AW12: 0 | AX12: 0 | AY12: 0
B13: Capital Cost | C13: Net Zero | D13: =IF('TECHNOLOGY REGISTER'!B65="","",'TECHNOLOGY REGISTER'!B65) -> PWRSOL | E13: Mn USD | F13: 0 | G13: 41.154 | H13: 0 | I13: 0 | J13: 0 | K13: 0 | L13: 0 | M13: 0 | N13: 0 | O13: 0 | P13: 0 | Q13: 0 | R13: 0 | S13: 0 | T13: 0 | U13: 0 | V13: 110.3518 | W13: 0 | X13: 0 | Y13: 0 | Z13: 0 | AA13: 0 | AB13: 0 | AC13: 0 | AD13: 0 | AE13: 70.5613 | AF13: 218.3748 | AG13: 198.4828 | AH13: 206.0219 | AI13: 23.9415 | AJ13: 63.8214 | AK13: 87.1221 | AL13: 15.0672 | AM13: 14.5138 | AN13: 20.9732 | AO13: 3.9983 | AP13: 124.9059 | AQ13: 17.1697 | AR13: 19.9166 | AS13: 18.8601 | AT13: 20.8675 | AU13: 20.9732 | AV13: 20.9732 | AW13: 20.9732 | AX13: 20.9732 | AY13: 91.8491
B14: Capital Cost | C14: Net Zero | D14: =IF('TECHNOLOGY REGISTER'!B66="","",'TECHNOLOGY REGISTER'!B66) -> PWRTRN | E14: Mn USD | F14: 29.242 | G14: 25.7349 | H14: 48.5603 | I14: 53.1132 | J14: 59.9757 | K14: 58.6536 | L14: 56.011 | M14: 64.762 | N14: 62.9314 | O14: 68.7988 | P14: 71.35 | Q14: 73.2156 | R14: 87.9064 | S14: 91.5697 | T14: 96.8191 | U14: 102.651 | V14: 108.1555 | W14: 111.9398 | X14: 119.3841 | Y14: 125.7539 | Z14: 132.9514 | AA14: 140.305 | AB14: 147.7846 | AC14: 156.2572 | AD14: 164.8982 | AE14: 173.6637 | AF14: 136.8356 | AG14: 136.8356 | AH14: 136.8356 | AI14: 136.8356 | AJ14: 136.8356 | AK14: 136.8356 | AL14: 136.8356 | AM14: 136.8356 | AN14: 136.8356 | AO14: 136.8356 | AP14: 136.8356 | AQ14: 136.8356 | AR14: 136.8356 | AS14: 136.8356 | AT14: 136.8356 | AU14: 136.8356 | AV14: 136.8356 | AW14: 136.8356 | AX14: 274.9511 | AY14: 149.39
B15: Capital Cost | C15: Net Zero | D15: =IF('TECHNOLOGY REGISTER'!B67="","",'TECHNOLOGY REGISTER'!B67) -> PWRWND | E15: Mn USD | F15: 19.0608 | G15: 86.8715 | H15: 74.4683 | I15: 170.526 | J15: 0 | K15: 426.0647 | L15: 0 | M15: 442.6991 | N15: 596.6576 | O15: 0 | P15: 435.4249 | Q15: 0 | R15: 157.8292 | S15: 1052.1194 | T15: 0 | U15: 0 | V15: 956.1161 | W15: 1023.2414 | X15: 1153.4401 | Y15: 876.8507 | Z15: 1580.9829 | AA15: 1012.8426 | AB15: 1421.1332 | AC15: 1309.4592 | AD15: 932.8625 | AE15: 1870.4236 | AF15: 632.1284 | AG15: 1024.8539 | AH15: 1057.6007 | AI15: 770.1707 | AJ15: 1132.069 | AK15: 795.103 | AL15: 1000.0284 | AM15: 1890.4747 | AN15: 839.6601 | AO15: 858.6878 | AP15: 1863.2176 | AQ15: 1867.1649 | AR15: 1994.2845 | AS15: 1718.8794 | AT15: 2420.7614 | AU15: 1852.5027 | AV15: 2260.7933 | AW15: 2149.1193 | AX15: 1772.5226 | AY15: 2705.9399
B16: Capital Cost | C16: Net Zero | D16: =IF('TECHNOLOGY REGISTER'!B68="","",'TECHNOLOGY REGISTER'!B68) -> PWRHFO | E16: Mn USD | F16: 0 | G16: 0 | H16: 0 | I16: 0 | J16: 0 | K16: 0 | L16: 0 | M16: 0 | N16: 0 | O16: 0 | P16: 0 | Q16: 0 | R16: 0 | S16: 0 | T16: 0 | U16: 0 | V16: 0 | W16: 0 | X16: 0 | Y16: 0 | Z16: 0 | AA16: 0 | AB16: 0 | AC16: 0 | AD16: 0 | AE16: 0 | AF16: 0 | AG16: 0 | AH16: 0 | AI16: 0 | AJ16: 0 | AK16: 0 | AL16: 0 | AM16: 0 | AN16: 0 | AO16: 0 | AP16: 0 | AQ16: 0 | AR16: 0 | AS16: 0 | AT16: 0 | AU16: 0 | AV16: 0 | AW16: 0 | AX16: 0 | AY16: 0
B17: Capital Cost | C17: Net Zero | D17: =IF('TECHNOLOGY REGISTER'!B69="","",'TECHNOLOGY REGISTER'!B69) -> PWRIMP | E17: Mn USD | F17: 0 | G17: 0 | H17: 0 | I17: 0 | J17: 0 | K17: 0 | L17: 0 | M17: 0 | N17: 0 | O17: 0 | P17: 0 | Q17: 0 | R17: 0 | S17: 0 | T17: 0 | U17: 0 | V17: 0 | W17: 0 | X17: 0 | Y17: 0 | Z17: 0 | AA17: 0 | AB17: 0 | AC17: 0 | AD17: 0 | AE17: 0 | AF17: 0 | AG17: 0 | AH17: 0 | AI17: 0 | AJ17: 0 | AK17: 0 | AL17: 0 | AM17: 0 | AN17: 0 | AO17: 0 | AP17: 0 | AQ17: 0 | AR17: 0 | AS17: 0 | AT17: 0 | AU17: 0 | AV17: 0 | AW17: 0 | AX17: 0 | AY17: 0
... B20: Capital Cost | C20: Net Zero | D20: =IF('TECHNOLOGY REGISTER'!B72="","",'TECHNOLOGY REGISTER'!B72) -> PWRHYD16 | E20: Mn USD | F20: 1.0453 | G20: 86.4096 | H20: 38.3269 | I20: 10.8012 | J20: 25.7835 | K20: 127.5239 | L20: 97.9077 | M20: 63.4135 | N20: 112.1932 | O20: 87.4549 | P20: 110.451 | Q20: 97.2109 | R20: 12.5433 | S20: 13.5886 | T20: 14.6339 | U20: 16.376 | V20: 17.7697 | W20: 19.5119 | X20: 21.254 | Y20: 22.9961 | Z20: 25.4351 | AA20: 27.8741 | AB20: 30.3131 | AC20: 33.1005 | AD20: 36.2363 | AE20: 39.7206 | AF20: 26.4804 | AG20: 26.4804 | AH20: 26.4804 | AI20: 26.4804 | AJ20: 26.4804 | AK20: 26.4804 | AL20: 26.4804 | AM20: 26.4804 | AN20: 26.4804 | AO20: 26.4804 | AP20: 26.4804 | AQ20: 26.4804 | AR20: 51.9155 | AS20: 35.191 | AT20: 27.5257 | AU20: 112.89 | AV20: 64.8072 | AW20: 37.2816 | AX20: 52.2639 | AY20: 154.0043
B21: Capital Cost | C21: Net Zero | D21: =IF('TECHNOLOGY REGISTER'!B73="","",'TECHNOLOGY REGISTER'!B73) | E21: Mn USD
B22: Capital Cost | C22: Net Zero | D22: =IF('TECHNOLOGY REGISTER'!B74="","",'TECHNOLOGY REGISTER'!B74) | E22: Mn USD
B23: Capital Cost | C23: Net Zero | D23: =IF('TECHNOLOGY REGISTER'!B75="","",'TECHNOLOGY REGISTER'!B75) | E23: Mn USD
B24: Capital Cost | C24: Net Zero | D24: =IF('TECHNOLOGY REGISTER'!B76="","",'TECHNOLOGY REGISTER'!B76) | E24: Mn USD
B25: Capital Cost | C25: Net Zero | D25: =IF('TECHNOLOGY REGISTER'!B77="","",'TECHNOLOGY REGISTER'!B77) | E25: Mn USD
B26: Capital Cost | C26: Net Zero | D26: =IF('TECHNOLOGY REGISTER'!B78="","",'TECHNOLOGY REGISTER'!B78) | E26: Mn USD
B27: Capital Cost | C27: Net Zero | D27: =IF('TECHNOLOGY REGISTER'!B79="","",'TECHNOLOGY REGISTER'!B79) | E27: Mn USD
B28: Capital Cost | C28: Net Zero | D28: =IF('TECHNOLOGY REGISTER'!B80="","",'TECHNOLOGY REGISTER'!B80) | E28: Mn USD
B29: Capital Cost | C29: Net Zero | D29: =IF('TECHNOLOGY REGISTER'!B81="","",'TECHNOLOGY REGISTER'!B81) | E29: Mn USD
B30: Capital Cost | C30: Net Zero | D30: =IF('TECHNOLOGY REGISTER'!B82="","",'TECHNOLOGY REGISTER'!B82) | E30: Mn USD
B31: Capital Cost | C31: Net Zero | D31: =IF('TECHNOLOGY REGISTER'!B83="","",'TECHNOLOGY REGISTER'!B83) | E31: Mn USD
B32: Capital Cost | C32: Net Zero | D32: =IF('TECHNOLOGY REGISTER'!B84="","",'TECHNOLOGY REGISTER'!B84) | E32: Mn USD
... B55: Capital Cost | C55: Net Zero | D55: =IF('TECHNOLOGY REGISTER'!B107="","",'TECHNOLOGY REGISTER'!B107) | E55: Mn USD
B56: 2. Actual Generation
B57: ActualGeneration | C57: Net Zero | D57: =IF('TECHNOLOGY REGISTER'!B58="","",'TECHNOLOGY REGISTER'!B58) -> BESS_TECH | E57: PJ | F57: 0.4703 | G57: 0.5186 | H57: 0.5531 | I57: 0.549 | J57: 0.5773 | K57: 0.63 | L57: 1.1445 | M57: 1.3177 | N57: 1.3128 | O57: 1.7174 | P57: 1.4057 | Q57: 1.2258 | R57: 1.445 | S57: 1.286 | T57: 1.9897 | U57: 1.6456 | V57: 2.133 | W57: 2.4669 | X57: 2.8583 | Y57: 3.3699 | Z57: 3.8566 | AA57: 4.4017 | AB57: 4.5967 | AC57: 4.6342 | AD57: 4.9793 | AE57: 5.7894 | AF57: 5.8087 | AG57: 6.0564 | AH57: 7.0198 | AI57: 7.2276 | AJ57: 7.6172 | AK57: 8.2527 | AL57: 8.5082 | AM57: 8.7839 | AN57: 9.0475 | AO57: 9.3896 | AP57: 9.7075 | AQ57: 10.0156 | AR57: 10.3179 | AS57: 10.6289 | AT57: 10.9531 | AU57: 11.2768 | AV57: 11.6005 | AW57: 11.9382 | AX57: 12.2801 | AY57: 12.5998
B58: ActualGeneration | C58: Net Zero | D58: =IF('TECHNOLOGY REGISTER'!B59="","",'TECHNOLOGY REGISTER'!B59) -> PWRBIO | E58: PJ | F58: 0.0536 | G58: 0.2113 | H58: 0.2113 | I58: 0.3373 | J58: 0.3373 | K58: 1.0973 | L58: 1.4125 | M58: 1.5828 | N58: 1.077 | O58: 1.7247 | P58: 1.7294 | Q58: 1.7294 | R58: 1.7294 | S58: 1.7294 | T58: 1.7294 | U58: 1.7294 | V58: 1.7294 | W58: 1.7294 | X58: 1.6979 | Y58: 1.6979 | Z58: 1.6979 | AA58: 1.6979 | AB58: 1.6979 | AC58: 1.6979 | AD58: 1.6979 | AE58: 0 | AF58: 0 | AG58: 0 | AH58: 0 | AI58: 0 | AJ58: 0 | AK58: 0 | AL58: 0 | AM58: 0 | AN58: 0 | AO58: 0 | AP58: 0 | AQ58: 0 | AR58: 0 | AS58: 0 | AT58: 0 | AU58: 0 | AV58: 0 | AW58: 0 | AX58: 0 | AY58: 0
B59: ActualGeneration | C59: Net Zero | D59: =IF('TECHNOLOGY REGISTER'!B60="","",'TECHNOLOGY REGISTER'!B60) -> PWRDIST | E59: PJ | F59: 50.1221 | G59: 51.6438 | H59: 54.5189 | I59: 57.6854 | J59: 61.2475 | K59: 64.6927 | L59: 68.0113 | M59: 71.8601 | N59: 75.5868 | O59: 79.687 | P59: 83.9275 | Q59: 88.3028 | R59: 93.5854 | S59: 99.0952 | T59: 104.9383 | U59: 111.1278 | V59: 117.6563 | W59: 124.4359 | X59: 131.6589 | Y59: 139.2903 | Z59: 147.3515 | AA59: 155.8671 | AB59: 164.8638 | AC59: 174.3679 | AD59: 184.4076 | AE59: 195.0127 | AF59: 203.201 | AG59: 211.3892 | AH59: 219.5775 | AI59: 227.7658 | AJ59: 235.954 | AK59: 244.1423 | AL59: 252.3306 | AM59: 260.5188 | AN59: 268.7071 | AO59: 276.8954 | AP59: 285.0836 | AQ59: 293.2719 | AR59: 301.4602 | AS59: 309.6485 | AT59: 317.8367 | AU59: 326.025 | AV59: 334.2132 | AW59: 342.4015 | AX59: 350.5898 | AY59: 358.7781
B60: ActualGeneration | C60: Net Zero | D60: =IF('TECHNOLOGY REGISTER'!B61="","",'TECHNOLOGY REGISTER'!B61) -> PWRGEO | E60: PJ | F60: 29.7337 | G60: 33.1873 | H60: 34.0681 | I60: 36.4531 | J60: 41.7923 | K60: 42.9816 | L60: 46.513 | M60: 47.677 | N60: 48.5712 | O60: 53.1168 | P60: 54.8315 | Q60: 60.1336 | R60: 64.6691 | S60: 67.6623 | T60: 75.1868 | U60: 83.9117 | V60: 85.5015 | W60: 87.8864 | X60: 88.3693 | Y60: 91.0523 | Z60: 89.3231 | AA60: 92.6024 | AB60: 93.6966 | AC60: 96.5287 | AD60: 101.0004 | AE60: 104.1306 | AF60: 107.1117 | AG60: 110.0929 | AH60: 113.074 | AI60: 116.0552 | AJ60: 118.9999 | AK60: 121.6279 | AL60: 124.471 | AM60: 127.3176 | AN60: 130.1633 | AO60: 133.0235 | AP60: 135.8781 | AQ60: 138.7272 | AR60: 141.5738 | AS60: 144.4215 | AT60: 147.2677 | AU60: 150.1135 | AV60: 152.9598 | AW60: 155.8053 | AX60: 158.651 | AY60: 161.5028
B61: ActualGeneration | C61: Net Zero | D61: =IF('TECHNOLOGY REGISTER'!B62="","",'TECHNOLOGY REGISTER'!B62) -> PWRHYD | E61: PJ | F61: 11.7784 | G61: 11.7784 | H61: 11.7784 | I61: 11.7784 | J61: 11.7784 | K61: 11.7784 | L61: 11.7784 | M61: 11.7784 | N61: 11.7784 | O61: 11.7784 | P61: 11.7784 | Q61: 11.7784 | R61: 11.7784 | S61: 11.7784 | T61: 11.7784 | U61: 11.7784 | V61: 11.7784 | W61: 10.0839 | X61: 10.084 | Y61: 10.084 | Z61: 10.084 | AA61: 10.084 | AB61: 10.0839 | AC61: 10.084 | AD61: 10.084 | AE61: 10.084 | AF61: 10.084 | AG61: 10.084 | AH61: 10.084 | AI61: 10.084 | AJ61: 10.0839 | AK61: 10.084 | AL61: 10.084 | AM61: 10.084 | AN61: 10.084 | AO61: 10.084 | AP61: 10.084 | AQ61: 10.084 | AR61: 10.084 | AS61: 10.084 | AT61: 10.084 | AU61: 10.084 | AV61: 10.084 | AW61: 10.084 | AX61: 10.084 | AY61: 10.084
B62: ActualGeneration | C62: Net Zero | D62: =IF('TECHNOLOGY REGISTER'!B63="","",'TECHNOLOGY REGISTER'!B63) -> PWRNGS | E62: PJ | F62: 0 | G62: 0 | H62: 0 | I62: 0 | J62: 0 | K62: 0 | L62: 0 | M62: 0 | N62: 0 | O62: 0 | P62: 0.0105 | Q62: 0.0256 | R62: 0.0728 | S62: 0.0714 | T62: 0.0402 | U62: 0 | V62: 0 | W62: 0 | X62: 0 | Y62: 0 | Z62: 0 | AA62: 0 | AB62: 0 | AC62: 0 | AD62: 0 | AE62: 0 | AF62: 0 | AG62: 0 | AH62: 0 | AI62: 0 | AJ62: 0 | AK62: 0 | AL62: 0 | AM62: 0 | AN62: 0 | AO62: 0 | AP62: 0 | AQ62: 0 | AR62: 0 | AS62: 0 | AT62: 0 | AU62: 0 | AV62: 0 | AW62: 0 | AX62: 0 | AY62: 0
B63: ActualGeneration | C63: Net Zero | D63: =IF('TECHNOLOGY REGISTER'!B64="","",'TECHNOLOGY REGISTER'!B64) -> PWRPHS | E63: PJ | F63: 0 | G63: 0 | H63: 0 | I63: 0 | J63: 0 | K63: 0 | L63: 0 | M63: 0 | N63: 0 | O63: 1.1228 | P63: 1.1289 | Q63: 1.4883 | R63: 1.5191 | S63: 1.3007 | T63: 1.3133 | U63: 2.6267 | V63: 2.7149 | W63: 2.644 | X63: 2.7097 | Y63: 2.7922 | Z63: 2.8817 | AA63: 2.9703 | AB63: 3.405 | AC63: 3.7498 | AD63: 3.9734 | AE63: 4.7185 | AF63: 4.9726 | AG63: 5.2737 | AH63: 5.342 | AI63: 5.3989 | AJ63: 5.426 | AK63: 5.4276 | AL63: 5.4292 | AM63: 5.4315 | AN63: 5.433 | AO63: 5.4398 | AP63: 5.4341 | AQ63: 5.4367 | AR63: 5.4385 | AS63: 5.4406 | AT63: 5.4421 | AU63: 5.4436 | AV63: 5.445 | AW63: 5.4465 | AX63: 5.4479 | AY63: 5.462
B64: ActualGeneration | C64: Net Zero | D64: =IF('TECHNOLOGY REGISTER'!B65="","",'TECHNOLOGY REGISTER'!B65) -> PWRSOL | E64: PJ | F64: 1.5589 | G64: 1.8066 | H64: 1.8066 | I64: 1.8066 | J64: 1.8066 | K64: 1.8066 | L64: 1.8066 | M64: 1.8066 | N64: 1.8066 | O64: 1.8066 | P64: 1.8066 | Q64: 1.8066 | R64: 1.8066 | S64: 1.4955 | T64: 1.4955 | U64: 1.4955 | V64: 2.0064 | W64: 1.7587 | X64: 1.5017 | Y64: 1.254 | Z64: 1.254 | AA64: 1.0063 | AB64: 1.0063 | AC64: 1.0063 | AD64: 1.0063 | AE64: 1.4835 | AF64: 3.1098 | AG64: 4.5548 | AH64: 6.0546 | AI64: 6.2289 | AJ64: 6.6935 | AK64: 7.3278 | AL64: 7.4375 | AM64: 7.5431 | AN64: 7.6958 | AO64: 7.7249 | AP64: 7.6279 | AQ64: 7.7529 | AR64: 7.8979 | AS64: 8.0352 | AT64: 8.1872 | AU64: 8.3399 | AV64: 8.4925 | AW64: 8.6452 | AX64: 8.7979 | AY64: 8.9529
B65: ActualGeneration | C65: Net Zero | D65: =IF('TECHNOLOGY REGISTER'!B66="","",'TECHNOLOGY REGISTER'!B66) -> PWRTRN | E65: PJ | F65: 54.5992 | G65: 56.1896 | H65: 59.2532 | I65: 62.6198 | J65: 66.4146 | K65: 70.0744 | L65: 73.5814 | M65: 77.6614 | N65: 81.6008 | O65: 85.9252 | P65: 90.4002 | Q65: 95.0003 | R65: 100.5754 | S65: 106.3824 | T65: 112.5223 | U65: 119.0315 | V65: 125.8895 | W65: 132.9869 | X65: 140.5561 | Y65: 148.5288 | Z65: 156.9573 | AA65: 165.8514 | AB65: 175.2193 | AC65: 185.1236 | AD65: 195.575 | AE65: 206.5813 | AF65: 215.2553 | AG65: 223.9293 | AH65: 232.6033 | AI65: 241.2773 | AJ65: 249.9513 | AK65: 258.6253 | AL65: 267.2993 | AM65: 275.9734 | AN65: 284.6474 | AO65: 293.3214 | AP65: 301.9954 | AQ65: 310.6694 | AR65: 319.3434 | AS65: 328.0174 | AT65: 336.6914 | AU65: 345.3655 | AV65: 354.0395 | AW65: 362.7135 | AX65: 371.3875 | AY65: 380.0615
...

Sheet EXISTING INFRASTRUCTURE
B2: EXISTING FINANCING REQUIREMENT
B3: ← Return to COVER
B5: Technology | C5: Year | D5: Financing Source | E5: Type of Finance | F5: Volume of Finance | G5: Currency | H5: Rate | I5: Term | J5: Grace period | K5: Schedule
B6: Geothermal | C6: 2014 | D6: Conc_IFI | E6: Equity | F6: 42.75 | G6: USD | H6: 0.168 | I6: 25 | J6: 0 | K6: EPP with Grace Years for Principal
B7: Geothermal | C7: 2014 | D7: Conc_DPS | E7: Equity | F7: 42.75 | G7: USD | H7: 0.168 | I7: 25 | J7: 0 | K7: Equity
B8: Geothermal | C8: 2014 | D8: Conc_DPS | E8: Loan | F8: 71.25 | G8: USD | H8: 0.04955 | I8: 21 | J8: 6.4 | K8: EPP with Grace Years for Principal
B9: Geothermal | C9: 2014 | D9: Comm_Intl | E9: Equity | F9: 17.1 | G9: USD | H9: 0.168 | I9: 25 | J9: 0 | K9: Equity
B10: Geothermal | C10: 2014 | D10: Comm_Intl | E10: Equity | F10: 11.4 | G10: USD | H10: 0.168 | I10: 25 | J10: 0 | K10: Equity
B11: Geothermal | C11: 2018 | D11: Conc_IFI | E11: Loan | F11: 192 | G11: USD | H11: 0.023903633 | I11: 32.66829 | J11: 6.9579862 | K11: EPP with Grace Years for Principal
B12: Solar PV | C12: 2022 | D12: Conc_IFI | E12: Loan | F12: 35 | G12: USD | H12: 0.04955 | I12: 15 | J12: 1 | K12: EPP with Grace Years for Principal
B13: Solar PV | C13: 2022 | D13: Comm_Intl | E13: Loan | F13: 41 | G13: USD | H13: 0.080329759 | I13: 15 | J13: 1.5 | K13: EPP with Grace Years for Principal
B14: Solar PV | C14: 2019 | D14: Comm_Intl | E14: Equity | F14: 11 | G14: USD | H14: 0.053 | I14: 24 | J14: 0 | K14: Equity
B15: Biomass | C15: 2015 | D15: Comm_Intl | E15: Loan | F15: 21 | G15: USD | H15: 0.080329759 | I15: 15 | J15: 1.5 | K15: EPP with Grace Years for Principal
B16: Biomass | C16: 2015 | D16: Comm_Intl | E16: Equity | F16: 8 | G16: USD | H16: 0.12 | I16: 30 | J16: 0 | K16: Equity
B17: Geothermal | C17: 2019 | D17: Conc_DPS | E17: Equity | F17: 19.6 | G17: USD | H17: 0.297 | I17: 25 | J17: 0 | K17: Equity
... B187: Oil | C187: 2013 | D187: Comm_Dom | E187: Equity | F187: 2.9 | G187: USD | H187: 0.147 | I187: 25 | J187: 0 | K187: Equity

Sheet NEW INFRASTRUCTURE
B1: FINANCING PARAMETERS - COST OF CAPITAL & INSTRUMENT STRUCTURE
B2: ← Return to COVER
B3: Technologies | C3: Comm_Intl | M3: Comm_Dom | W3: Conc_IFI | AG3: Conc_DPS
C4: Debt | F4: Equity | H4: Financing Shares | K4: Foreign Currency Shares | M4: Debt | P4: Equity | R4: Financing Shares | U4: Foreign Currency Shares | W4: Debt | Z4: Equity | AB4: Financing Shares | AE4: Foreign Currency Shares | AG4: Debt | AJ4: Equity | AL4: Financing Shares | AO4: Foreign Currency Shares
C5: Interest Rate | D5: Grace Period | E5: Loan Term | F5: Rate of Return | G5: Project Life | H5: Debt Share | I5: Equity Share | J5: Share of Finance | K5: Debt | L5: Equity | M5: Interest Rate | N5: Grace Period | O5: Loan Term | P5: Rate of Return | Q5: Project Life | R5: Debt Share | S5: Equity Share | T5: Share of Finance | U5: Debt | V5: Equity | W5: Interest Rate | X5: Grace Period | Y5: Loan Term | Z5: Rate of Return | AA5: Project Life | AB5: Debt Share | AC5: Equity Share | AD5: Share of Finance | AE5: Debt | AF5: Equity | AG5: Interest Rate | AH5: Grace Period | AI5: Loan Term | AJ5: Rate of Return | AK5: Project Life | AL5: Debt Share | AM5: Equity Share | AN5: Share of Finance | AO5: Debt | AP5: Equity
B6: =IF('TECHNOLOGY REGISTER'!D7="","",'TECHNOLOGY REGISTER'!D7) -> Biomass | C6: 0.1866 | D6: 0 | E6: 15.77 | F6: 0.225 | G6: 40 | H6: 0.63 | I6: 0.37 | J6: 0 | K6: 1 | L6: 1 | M6: 0.1637 | N6: 0 | O6: 18.54 | P6: 0.202 | Q6: 40 | R6: 0.63 | S6: 0.37 | T6: 0.095 | U6: 0 | V6: 0 | W6: 0.0469 | X6: 4.59 | Y6: 28.25 | Z6: 0.085 | AA6: 40 | AB6: 0.964 | AC6: 0.036 | AD6: 0.672 | AE6: 1 | AF6: 1 | AG6: 0.1269 | AH6: 7.1 | AI6: 22.64 | AJ6: 0.202 | AK6: 40 | AL6: 0.55 | AM6: 0.45 | AN6: 0.233 | AO6: 0 | AP6: 0
B7: =IF('TECHNOLOGY REGISTER'!D8="","",'TECHNOLOGY REGISTER'!D8) -> Geothermal | C7: 0.18 | D7: 0 | E7: 15.77 | F7: 0.218 | G7: 30 | H7: 0.63 | I7: 0.37 | J7: 0.071 | K7: 1 | L7: 1 | M7: 0.157 | N7: 0 | O7: 18.54 | P7: 0.195 | Q7: 30 | R7: 0.63 | S7: 0.37 | T7: 0.003 | U7: 0 | V7: 0 | W7: 0.0469 | X7: 4.59 | Y7: 28.25 | Z7: 0.085 | AA7: 30 | AB7: 0.964 | AC7: 0.036 | AD7: 0.752 | AE7: 1 | AF7: 1 | AG7: 0.127 | AH7: 7.1 | AI7: 22.64 | AJ7: 0.195 | AK7: 30 | AL7: 0.55 | AM7: 0.45 | AN7: 0.175 | AO7: 0 | AP7: 0
B8: =IF('TECHNOLOGY REGISTER'!D9="","",'TECHNOLOGY REGISTER'!D9) -> Solar PV | C8: 0.1757 | D8: 0 | E8: 15.77 | F8: 0.214 | G8: 25 | H8: 0.63 | I8: 0.37 | J8: 0.184 | K8: 1 | L8: 1 | M8: 0.153 | N8: 0 | O8: 18.54 | P8: 0.191 | Q8: 25 | R8: 0.63 | S8: 0.37 | T8: 0.17 | U8: 0 | V8: 0 | W8: 0.0469 | X8: 4.59 | Y8: 28.25 | Z8: 0.085 | AA8: 25 | AB8: 0.398 | AC8: 0.602 | AD8: 0.5 | AE8: 1 | AF8: 1 | AG8: 0.127 | AH8: 7.1 | AI8: 22.64 | AJ8: 0.191 | AK8: 25 | AL8: 0.55 | AM8: 0.45 | AN8: 0.145 | AO8: 0 | AP8: 0
B9: =IF('TECHNOLOGY REGISTER'!D10="","",'TECHNOLOGY REGISTER'!D10) -> CSP | C9: 0.173 | D9: 0 | E9: 15.77 | F9: 0.2 | G9: 50 | H9: 0.63 | I9: 0.37 | J9: 0.787 | K9: 1 | L9: 1 | M9: 0.1498 | N9: 0 | O9: 18.54 | P9: 0.177 | Q9: 50 | R9: 0.63 | S9: 0.37 | T9: 0.192 | U9: 0 | V9: 0 | W9: 0.0469 | X9: 4.59 | Y9: 28.25 | Z9: 0.085 | AA9: 50 | AB9: 0.964 | AC9: 0.036 | AD9: 0 | AE9: 1 | AF9: 1 | AG9: 0.127 | AH9: 7.1 | AI9: 22.64 | AJ9: 0.177 | AK9: 50 | AL9: 0.55 | AM9: 0.45 | AN9: 0.02 | AO9: 0 | AP9: 0
B10: =IF('TECHNOLOGY REGISTER'!D11="","",'TECHNOLOGY REGISTER'!D11) -> Hydropower | C10: 0.1761 | D10: 0 | E10: 15.77 | F10: 0.214 | G10: 24 | H10: 0.63 | I10: 0.37 | J10: 1 | K10: 1 | L10: 1 | M10: 0.153 | N10: 0 | O10: 18.54 | P10: 0.191 | Q10: 24 | R10: 0.63 | S10: 0.37 | T10: 0 | U10: 0 | V10: 0 | W10: 0.0469 | X10: 4.59 | Y10: 28.25 | Z10: 0.085 | AA10: 24 | AB10: 0.964 | AC10: 0.036 | AD10: 0 | AE10: 1 | AF10: 1 | AG10: 0.127 | AH10: 7.1 | AI10: 22.64 | AJ10: 0.191 | AK10: 24 | AL10: 0.55 | AM10: 0.45 | AN10: 0 | AO10: 0 | AP10: 0
B11: =IF('TECHNOLOGY REGISTER'!D12="","",'TECHNOLOGY REGISTER'!D12) -> Nuclear | C11: 0.1727 | D11: 0 | E11: 15.77 | F11: 0.203 | G11: 25 | H11: 0.63 | I11: 0.37 | J11: 0.388 | K11: 1 | L11: 1 | M11: 0.15 | N11: 0 | O11: 18.54 | P11: 0.18 | Q11: 25 | R11: 0.63 | S11: 0.37 | T11: 0.215 | U11: 0 | V11: 0 | W11: 0.0469 | X11: 4.59 | Y11: 28.25 | Z11: 0.085 | AA11: 25 | AB11: 0.964 | AC11: 0.036 | AD11: 0.194 | AE11: 1 | AF11: 1 | AG11: 0.127 | AH11: 7.1 | AI11: 22.64 | AJ11: 0.18 | AK11: 25 | AL11: 0.55 | AM11: 0.45 | AN11: 0.203 | AO11: 0 | AP11: 0
B12: =IF('TECHNOLOGY REGISTER'!D13="","",'TECHNOLOGY REGISTER'!D13) -> Wind | J12: 0 | T12: 0 | AB12: 1 | AC12: 1 | AD12: 0 | AN12: 0
B13: =IF('TECHNOLOGY REGISTER'!D14="","",'TECHNOLOGY REGISTER'!D14) -> Coal | C13: 0.1762 | D13: 0 | E13: 15.77 | F13: 0.214 | G13: 60 | H13: 0.63 | I13: 0.37 | J13: 1 | K13: 1 | L13: 1 | M13: 0.153 | N13: 0 | O13: 18.54 | P13: 0.192 | Q13: 60 | R13: 0.63 | S13: 0.37 | T13: 0 | U13: 0 | V13: 0 | W13: 0.0469 | X13: 4.59 | Y13: 28.25 | Z13: 0.085 | AA13: 60 | AB13: 0.964 | AC13: 0.036 | AD13: 0 | AE13: 1 | AF13: 1 | AG13: 0.127 | AH13: 7.1 | AI13: 22.64 | AJ13: 0.192 | AK13: 60 | AL13: 0.55 | AM13: 0.45 | AN13: 0 | AO13: 0 | AP13: 0
B14: =IF('TECHNOLOGY REGISTER'!D15="","",'TECHNOLOGY REGISTER'!D15) -> Oil | C14: 0.1741 | D14: 0 | E14: 15.77 | F14: 0.212 | G14: 30 | H14: 0.63 | I14: 0.37 | J14: 0.39 | K14: 1 | L14: 1 | M14: 0.1512 | N14: 0 | O14: 18.54 | P14: 0.189 | Q14: 30 | R14: 0.63 | S14: 0.37 | T14: 0 | U14: 0 | V14: 0 | W14: 0.0469 | X14: 4.59 | Y14: 28.25 | Z14: 0.085 | AA14: 30 | AB14: 0.964 | AC14: 0.036 | AD14: 0.61 | AE14: 1 | AF14: 1 | AG14: 0.127 | AH14: 7.1 | AI14: 22.64 | AJ14: 0.189 | AK14: 30 | AL14: 0.55 | AM14: 0.45 | AN14: 0 | AO14: 0 | AP14: 0
B15: =IF('TECHNOLOGY REGISTER'!D16="","",'TECHNOLOGY REGISTER'!D16) -> Gas | J15: 0 | T15: 0 | AB15: 1 | AC15: 1 | AD15: 0 | AN15: 0
B16: =IF('TECHNOLOGY REGISTER'!D17="","",'TECHNOLOGY REGISTER'!D17) -> Transmission | C16: 0.1762 | D16: 0 | E16: 15.77 | F16: 0.214 | G16: 50 | H16: 0.63 | I16: 0.37 | J16: 0.375 | K16: 1 | L16: 1 | M16: 0.153 | N16: 0 | O16: 18.54 | P16: 0.192 | Q16: 50 | R16: 0.63 | S16: 0.37 | T16: 0.197 | U16: 0 | V16: 0 | W16: 0.0469 | X16: 4.59 | Y16: 28.25 | Z16: 0.085 | AA16: 50 | AB16: 0.964 | AC16: 0.036 | AD16: 0.247 | AE16: 1 | AF16: 1 | AG16: 0.127 | AH16: 7.1 | AI16: 22.64 | AJ16: 0.192 | AK16: 50 | AL16: 0.55 | AM16: 0.45 | AN16: 0.18 | AO16: 0 | AP16: 0
B17: =IF('TECHNOLOGY REGISTER'!D18="","",'TECHNOLOGY REGISTER'!D18) -> Distribution | C17: 0.1762 | D17: 0 | E17: 15.77 | F17: 0.214 | G17: 70 | H17: 0.63 | I17: 0.37 | J17: 0.646 | K17: 1 | L17: 1 | M17: 0.153 | N17: 0 | O17: 18.54 | P17: 0.192 | Q17: 70 | R17: 0.63 | S17: 0.37 | T17: 0 | U17: 0 | V17: 0 | W17: 0.0469 | X17: 4.59 | Y17: 28.25 | Z17: 0.085 | AA17: 70 | AB17: 0.964 | AC17: 0.036 | AD17: 0.227 | AE17: 1 | AF17: 1 | AG17: 0.127 | AH17: 7.1 | AI17: 22.64 | AJ17: 0.192 | AK17: 70 | AL17: 0.55 | AM17: 0.45 | AN17: 0.127 | AO17: 0 | AP17: 0
B18: =IF('TECHNOLOGY REGISTER'!D19="","",'TECHNOLOGY REGISTER'!D19) -> Imports | C18: 0.1762 | D18: 0 | E18: 15.77 | F18: 0.214 | G18: 90 | H18: 0.63 | I18: 0.37 | J18: 0.917 | K18: 1 | L18: 1 | M18: 0.153 | N18: 0 | O18: 18.54 | P18: 0.192 | Q18: 90 | R18: 0.63 | S18: 0.37 | T18: -0.197 | U18: 0 | V18: 0 | W18: 0.0469 | X18: 4.59 | Y18: 28.25 | Z18: 0.085 | AA18: 90 | AB18: 0.964 | AC18: 0.036 | AD18: 0.207 | AE18: 1 | AF18: 1 | AG18: 0.127 | AH18: 7.1 | AI18: 22.64 | AJ18: 0.192 | AK18: 90 | AL18: 0.55 | AM18: 0.45 | AN18: 0.074 | AO18: 0 | AP18: 0
B19: =IF('TECHNOLOGY REGISTER'!D20="","",'TECHNOLOGY REGISTER'!D20) -> Energy Exports | C19: 0.1762 | D19: 0 | E19: 15.77 | F19: 0.214 | G19: 110 | H19: 0.63 | I19: 0.37 | J19: 1.188 | K19: 1 | L19: 1 | M19: 0.153 | N19: 0 | O19: 18.54 | P19: 0.192 | Q19: 110 | R19: 0.63 | S19: 0.37 | T19: -0.394 | U19: 0 | V19: 0 | W19: 0.0469 | X19: 4.59 | Y19: 28.25 | Z19: 0.085 | AA19: 110 | AB19: 0.964 | AC19: 0.036 | AD19: 0.187 | AE19: 1 | AF19: 1 | AG19: 0.127 | AH19: 7.1 | AI19: 22.64 | AJ19: 0.192 | AK19: 110 | AL19: 0.55 | AM19: 0.45 | AN19: 0.021 | AO19: 0 | AP19: 0
B20: =IF('TECHNOLOGY REGISTER'!D21="","",'TECHNOLOGY REGISTER'!D21) -> Direct Solar | C20: 0.1762 | D20: 0 | E20: 15.77 | F20: 0.214 | G20: 130 | H20: 0.63 | I20: 0.37 | J20: 1.459 | K20: 1 | L20: 1 | M20: 0.153 | N20: 0 | O20: 18.54 | P20: 0.192 | Q20: 130 | R20: 0.63 | S20: 0.37 | T20: -0.591 | U20: 0 | V20: 0 | W20: 0.0469 | X20: 4.59 | Y20: 28.25 | Z20: 0.085 | AA20: 130 | AB20: 0.964 | AC20: 0.036 | AD20: 0.167 | AE20: 1 | AF20: 1 | AG20: 0.127 | AH20: 7.1 | AI20: 22.64 | AJ20: 0.192 | AK20: 130 | AL20: 0.55 | AM20: 0.45 | AN20: -0.032 | AO20: 0 | AP20: 0
B21: =IF('TECHNOLOGY REGISTER'!D22="","",'TECHNOLOGY REGISTER'!D22) -> Direct Oil | C21: 0.1762 | D21: 0 | E21: 15.77 | F21: 0.214 | G21: 150 | H21: 0.63 | I21: 0.37 | J21: 1.73 | K21: 1 | L21: 1 | M21: 0.153 | N21: 0 | O21: 18.54 | P21: 0.192 | Q21: 150 | R21: 0.63 | S21: 0.37 | T21: -0.788 | U21: 0 | V21: 0 | W21: 0.0469 | X21: 4.59 | Y21: 28.25 | Z21: 0.085 | AA21: 150 | AB21: 0.964 | AC21: 0.036 | AD21: 0.147 | AE21: 1 | AF21: 1 | AG21: 0.127 | AH21: 7.1 | AI21: 22.64 | AJ21: 0.192 | AK21: 150 | AL21: 0.55 | AM21: 0.45 | AN21: -0.085 | AO21: 0 | AP21: 0
B22: =IF('TECHNOLOGY REGISTER'!D23="","",'TECHNOLOGY REGISTER'!D23) -> Direct Hydro | C22: 0.1762 | D22: 0 | E22: 15.77 | F22: 0.214 | G22: 170 | H22: 0.63 | I22: 0.37 | J22: 2.001 | K22: 1 | L22: 1 | M22: 0.153 | N22: 0 | O22: 18.54 | P22: 0.192 | Q22: 170 | R22: 0.63 | S22: 0.37 | T22: -0.985 | U22: 0 | V22: 0 | W22: 0.0469 | X22: 4.59 | Y22: 28.25 | Z22: 0.085 | AA22: 170 | AB22: 0.964 | AC22: 0.036 | AD22: 0.127 | AE22: 1 | AF22: 1 | AG22: 0.127 | AH22: 7.1 | AI22: 22.64 | AJ22: 0.192 | AK22: 170 | AL22: 0.55 | AM22: 0.45 | AN22: -0.138 | AO22: 0 | AP22: 0
B23: =IF('TECHNOLOGY REGISTER'!D24="","",'TECHNOLOGY REGISTER'!D24)
B24: =IF('TECHNOLOGY REGISTER'!D25="","",'TECHNOLOGY REGISTER'!D25)
B25: =IF('TECHNOLOGY REGISTER'!D26="","",'TECHNOLOGY REGISTER'!D26)
B26: =IF('TECHNOLOGY REGISTER'!D27="","",'TECHNOLOGY REGISTER'!D27)
B27: =IF('TECHNOLOGY REGISTER'!D28="","",'TECHNOLOGY REGISTER'!D28)
B28: =IF('TECHNOLOGY REGISTER'!D29="","",'TECHNOLOGY REGISTER'!D29)
B29: =IF('TECHNOLOGY REGISTER'!D30="","",'TECHNOLOGY REGISTER'!D30)
B30: =IF('TECHNOLOGY REGISTER'!D31="","",'TECHNOLOGY REGISTER'!D31)
B31: =IF('TECHNOLOGY REGISTER'!D32="","",'TECHNOLOGY REGISTER'!D32)
B32: =IF('TECHNOLOGY REGISTER'!D33="","",'TECHNOLOGY REGISTER'!D33)
B33: =IF('TECHNOLOGY REGISTER'!D34="","",'TECHNOLOGY REGISTER'!D34)
B34: =IF('TECHNOLOGY REGISTER'!D35="","",'TECHNOLOGY REGISTER'!D35)
... B55: =IF('TECHNOLOGY REGISTER'!D56="","",'TECHNOLOGY REGISTER'!D56)

Sheet PPA REVENUE
B1: PPA REVENUE
B2: ← Return to COVER
B4: Variable | C4: Scenario | D4: Technology | E4: Currency | F4: Unit | G4: 2025 | H4: 2026 | I4: 2027 | J4: 2028 | K4: 2029 | L4: 2030 | M4: 2031 | N4: 2032 | O4: 2033 | P4: 2034 | Q4: 2035 | R4: 2036 | S4: 2037 | T4: 2038 | U4: 2039 | V4: 2040 | W4: 2041 | X4: 2042 | Y4: 2043 | Z4: 2044 | AA4: 2045 | AB4: 2046 | AC4: 2047 | AD4: 2048 | AE4: 2049 | AF4: 2050 | AG4: 2051 | AH4: 2052 | AI4: 2053 | AJ4: 2054 | AK4: 2055 | AL4: 2056 | AM4: 2057 | AN4: 2058 | AO4: 2059 | AP4: 2060 | AQ4: 2061 | AR4: 2062 | AS4: 2063 | AT4: 2064 | AU4: 2065 | AV4: 2066 | AW4: 2067 | AX4: 2068 | AY4: 2069 | AZ4: 2070
B5: 1. PPA Contracted Generation
B6: PPA Contracted Generation | C6: Net Zero | D6: =IF('TECHNOLOGY REGISTER'!D7="","",'TECHNOLOGY REGISTER'!D7) -> Biomass | F6: GWh/Year | G6: 130.63899 | H6: 144.05567 | I6: 153.63901 | J6: 152.50012 | K6: 160.36124 | L6: 175.00014 | M6: 317.91692 | N6: 366.02807 | O6: 364.66696 | P6: 477.05594 | Q6: 390.47253 | R6: 340.50027 | S6: 401.38921 | T6: 357.22251 | U6: 552.69489 | V6: 457.11148 | W6: 592.50047 | X6: 685.25055 | Y6: 793.97286 | Z6: 936.08408 | AA6: 1071.2786 | AB6: 1222.6954 | AC6: 1276.8621 | AD6: 1287.2788 | AE6: 1383.14 | AF6: 1608.168 | AG6: 1613.5291 | AH6: 1682.3347 | AI6: 1949.946 | AJ6: 2007.6683 | AK6: 2115.8906 | AL6: 2292.4185 | AM6: 2363.3908 | AN6: 2439.9742 | AO6: 2513.1965 | AP6: 2608.2243 | AQ6: 2696.5299 | AR6: 2782.1133 | AS6: 2866.0856 | AT6: 2952.4746 | AU6: 3042.5302 | AV6: 3132.447 | AW6: 3222.3637 | AX6: 3316.1693 | AY6: 3411.1416 | AZ6: 3499.9472
B7: PPA Contracted Generation | C7: Net Zero | D7: =IF('TECHNOLOGY REGISTER'!D8="","",'TECHNOLOGY REGISTER'!D8) -> Geothermal | F7: GWh/Year | G7: 14.888901 | H7: 58.694491 | I7: 58.694491 | J7: 93.694519 | K7: 93.694519 | L7: 304.8058 | M7: 392.36143 | N7: 439.66702 | O7: 299.16691 | P7: 479.08372 | Q7: 480.38927 | R7: 480.38927 | S7: 480.38927 | T7: 480.38927 | U7: 480.38927 | V7: 480.38927 | W7: 480.38927 | X7: 480.38927 | Y7: 471.63927 | Z7: 471.63927 | AA7: 471.63927 | AB7: 471.63927 | AC7: 471.63927 | AD7: 471.63927 | AE7: 471.63927 | AF7: 0 | AG7: 0 | AH7: 0 | AI7: 0 | AJ7: 0 | AK7: 0 | AL7: 0 | AM7: 0 | AN7: 0 | AO7: 0 | AP7: 0 | AQ7: 0 | AR7: 0 | AS7: 0 | AT7: 0 | AU7: 0 | AV7: 0 | AW7: 0 | AX7: 0 | AY7: 0 | AZ7: 0
B8: PPA Contracted Generation | C8: Net Zero | D8: =IF('TECHNOLOGY REGISTER'!D9="","",'TECHNOLOGY REGISTER'!D9) -> Solar PV | F8: GWh/Year | G8: 13922.817 | H8: 14345.511 | I8: 15144.151 | J8: 16023.735 | K8: 17013.208 | L8: 17970.209 | M8: 18892.043 | N8: 19961.155 | O8: 20996.35 | P8: 22135.295 | Q8: 23313.213 | R8: 24528.575 | S8: 25995.965 | T8: 27526.466 | U8: 29149.551 | V8: 30868.858 | W8: 32682.332 | X8: 34565.555 | Y8: 36571.946 | Z8: 38691.781 | AA8: 40931.005 | AB8: 43296.451 | AC8: 45795.537 | AD8: 48435.567 | AE8: 51224.374 | AF8: 54170.238 | AG8: 56444.767 | AH8: 58719.269 | AI8: 60993.799 | AJ8: 63268.328 | AK8: 65542.83 | AL8: 67817.36 | AM8: 70091.889 | AN8: 72366.391 | AO8: 74640.921 | AP8: 76915.45 | AQ8: 79189.952 | AR8: 81464.482 | AS8: 83739.011 | AT8: 86013.541 | AU8: 88288.043 | AV8: 90562.572 | AW8: 92837.074 | AX8: 95111.604 | AY8: 97386.133 | AZ8: 99660.663
B9: PPA Contracted Generation | C9: Net Zero | D9: =IF('TECHNOLOGY REGISTER'!D10="","",'TECHNOLOGY REGISTER'!D10) -> CSP | F9: GWh/Year | G9: 8259.3677 | H9: 9218.7018 | I9: 9463.3687 | J9: 10125.869 | K9: 11608.982 | L9: 11939.343 | M9: 12920.288 | N9: 13243.622 | O9: 13492.011 | P9: 14754.678 | Q9: 15230.984 | R9: 16703.791 | S9: 17963.653 | T9: 18795.098 | U9: 20885.239 | V9: 23308.824 | W9: 23750.436 | X9: 24412.908 | Y9: 24547.047 | Z9: 25292.326 | AA9: 24811.992 | AB9: 25722.909 | AC9: 26026.854 | AD9: 26813.549 | AE9: 28055.689 | AF9: 28925.19 | AG9: 29753.274 | AH9: 30581.386 | AI9: 31409.47 | AJ9: 32237.581 | AK9: 33055.554 | AL9: 33785.555 | AM9: 34575.305 | AN9: 35366.028 | AO9: 36156.501 | AP9: 36951.002 | AQ9: 37743.947 | AR9: 38535.364 | AS9: 39326.087 | AT9: 40117.115 | AU9: 40907.727 | AV9: 41698.228 | AW9: 42488.867 | AX9: 43279.285 | AY9: 44069.757 | AZ9: 44861.925
B10: PPA Contracted Generation | C10: Net Zero | D10: =IF('TECHNOLOGY REGISTER'!D11="","",'TECHNOLOGY REGISTER'!D11) -> Hydropower | F10: GWh/Year | G10: 3271.7804 | H10: 3271.7804 | I10: 3271.7804 | J10: 3271.7804 | K10: 3271.7804 | L10: 3271.7804 | M10: 3271.7804 | N10: 3271.7804 | O10: 3271.7804 | P10: 3271.7804 | Q10: 3271.7804 | R10: 3271.7804 | S10: 3271.7804 | T10: 3271.7804 | U10: 3271.7804 | V10: 3271.7804 | W10: 3271.7804 | X10: 2801.0856 | Y10: 2801.1134 | Z10: 2801.1134 | AA10: 2801.1134 | AB10: 2801.1134 | AC10: 2801.0856 | AD10: 2801.1134 | AE10: 2801.1134 | AF10: 2801.1134 | AG10: 2801.1134 | AH10: 2801.1134 | AI10: 2801.1134 | AJ10: 2801.1134 | AK10: 2801.0856 | AL10: 2801.1134 | AM10: 2801.1134 | AN10: 2801.1134 | AO10: 2801.1134 | AP10: 2801.1134 | AQ10: 2801.1134 | AR10: 2801.1134 | AS10: 2801.1134 | AT10: 2801.1134 | AU10: 2801.1134 | AV10: 2801.1134 | AW10: 2801.1134 | AX10: 2801.1134 | AY10: 2801.1134 | AZ10: 2801.1134
B11: PPA Contracted Generation | C11: Net Zero | D11: =IF('TECHNOLOGY REGISTER'!D12="","",'TECHNOLOGY REGISTER'!D12) -> Nuclear | F11: GWh/Year | G11: 0 | H11: 0 | I11: 0 | J11: 0 | K11: 0 | L11: 0 | M11: 0 | N11: 0 | O11: 0 | P11: 0 | Q11: 2.916669 | R11: 7.1111168 | S11: 20.222238 | T11: 19.833349 | U11: 11.166676 | V11: 0 | W11: 0 | X11: 0 | Y11: 0 | Z11: 0 | AA11: 0 | AB11: 0 | AC11: 0 | AD11: 0 | AE11: 0 | AF11: 0 | AG11: 0 | AH11: 0 | AI11: 0 | AJ11: 0 | AK11: 0 | AL11: 0 | AM11: 0 | AN11: 0 | AO11: 0 | AP11: 0 | AQ11: 0 | AR11: 0 | AS11: 0 | AT11: 0 | AU11: 0 | AV11: 0 | AW11: 0 | AX11: 0 | AY11: 0 | AZ11: 0
B12: PPA Contracted Generation | C12: Net Zero | D12: =IF('TECHNOLOGY REGISTER'!D13="","",'TECHNOLOGY REGISTER'!D13) -> Wind | F12: GWh/Year | G12: 0 | H12: 0 | I12: 0 | J12: 0 | K12: 0 | L12: 0 | M12: 0 | N12: 0 | O12: 0 | P12: 311.88914 | Q12: 313.58358 | R12: 413.417 | S12: 421.97256 | T12: 361.30584 | U12: 364.80585 | V12: 729.63947 | W12: 754.13949 | X12: 734.44503 | Y12: 752.69505 | Z12: 775.61173 | AA12: 800.47286 | AB12: 825.08399 | AC12: 945.83409 | AD12: 1041.6119 | AE12: 1103.7231 | AF12: 1310.6955 | AG12: 1381.2789 | AH12: 1464.9178 | AI12: 1483.8901 | AJ12: 1499.6956 | AK12: 1507.2234 | AL12: 1507.6679 | AM12: 1508.1123 | AN12: 1508.7512 | AO12: 1509.1679 | AP12: 1511.0568 | AQ12: 1509.4734 | AR12: 1510.1957 | AS12: 1510.6957 | AT12: 1511.279 | AU12: 1511.6957 | AV12: 1512.1123 | AW12: 1512.5012 | AX12: 1512.9179 | AY12: 1513.3068 | AZ12: 1517.2234
B13: PPA Contracted Generation | C13: Net Zero | D13: =IF('TECHNOLOGY REGISTER'!D14="","",'TECHNOLOGY REGISTER'!D14) -> Coal | F13: GWh/Year | G13: 433.02812 | H13: 501.83373 | I13: 501.83373 | J13: 501.83373 | K13: 501.83373 | L13: 501.83373 | M13: 501.83373 | N13: 501.83373 | O13: 501.83373 | P13: 501.83373 | Q13: 501.83373 | R13: 501.83373 | S13: 501.83373 | T13: 415.417 | U13: 415.417 | V13: 415.417 | W13: 557.33378 | X13: 488.52817 | Y13: 417.13922 | Z13: 348.33361 | AA13: 348.33361 | AB13: 279.528 | AC13: 279.528 | AD13: 279.528 | AE13: 279.528 | AF13: 412.08366 | AG13: 863.83402 | AH13: 1265.2232 | AI13: 1681.8347 | AJ13: 1730.2514 | AK13: 1859.307 | AL13: 2035.5016 | AM13: 2065.9739 | AN13: 2095.3072 | AO13: 2137.7239 | AP13: 2145.8073 | AQ13: 2118.8628 | AR13: 2153.5851 | AS13: 2193.8629 | AT13: 2232.0018 | AU13: 2274.224 | AV13: 2316.6407 | AW13: 2359.0297 | AX13: 2401.4464 | AY13: 2443.8631 | AZ13: 2486.9187
B14: PPA Contracted Generation | C14: Net Zero | D14: =IF('TECHNOLOGY REGISTER'!D15="","",'TECHNOLOGY REGISTER'!D15) -> Oil | F14: GWh/Year | G14: 15166.457 | H14: 15608.235 | I14: 16459.235 | J14: 17394.403 | K14: 18448.515 | L14: 19465.127 | M14: 20439.294 | N14: 21572.628 | O14: 22666.907 | P14: 23868.13 | Q14: 25111.187 | R14: 26388.993 | S14: 27937.633 | T14: 29550.69 | U14: 31256.219 | V14: 33064.332 | W14: 34969.334 | X14: 36940.835 | Y14: 39043.392 | Z14: 41258.033 | AA14: 43599.285 | AB14: 46069.87 | AC14: 48672.067 | AD14: 51423.263 | AE14: 54326.432 | AF14: 57383.74 | AG14: 59793.187 | AH14: 62202.633 | AI14: 64612.079 | AJ14: 67021.526 | AK14: 69430.972 | AL14: 71840.419 | AM14: 74249.865 | AN14: 76659.339 | AO14: 79068.785 | AP14: 81478.232 | AQ14: 83887.678 | AR14: 86297.125 | AS14: 88706.571 | AT14: 91116.017 | AU14: 93525.464 | AV14: 95934.938 | AW14: 98344.384 | AX14: 100753.83 | AY14: 103163.28 | AZ14: 105572.72
B15: PPA Contracted Generation | C15: Net Zero | D15: =IF('TECHNOLOGY REGISTER'!D16="","",'TECHNOLOGY REGISTER'!D16) -> Gas | F15: GWh/Year | G15: 0 | H15: 0 | I15: 0 | J15: 0 | K15: 0 | L15: 0 | M15: 0 | N15: 0 | O15: 0 | P15: 0 | Q15: 0 | R15: 0 | S15: 0 | T15: 0 | U15: 0 | V15: 0 | W15: 0 | X15: 0 | Y15: 0 | Z15: 0 | AA15: 0 | AB15: 0 | AC15: 0 | AD15: 0 | AE15: 0 | AF15: 0 | AG15: 0 | AH15: 0 | AI15: 0 | AJ15: 0 | AK15: 0 | AL15: 0 | AM15: 0 | AN15: 0 | AO15: 0 | AP15: 0 | AQ15: 0 | AR15: 0 | AS15: 0 | AT15: 0 | AU15: 0 | AV15: 0 | AW15: 0 | AX15: 0 | AY15: 0 | AZ15: 0
B16: PPA Contracted Generation | C16: Net Zero | D16: =IF('TECHNOLOGY REGISTER'!D17="","",'TECHNOLOGY REGISTER'!D17) -> Transmission | F16: GWh/Year | G16: 680.50054 | H16: 112.77787 | I16: 263.94466 | J16: 293.36135 | K16: 230.97241 | L16: 206.72239 | M16: 217.66684 | N16: 238.33352 | O16: 204.66683 | P16: 0.5000004 | Q16: 18.166681 | R16: 0 | S16: 0 | T16: 0 | U16: 0 | V16: 0 | W16: 0 | X16: 0 | Y16: 0 | Z16: 0 | AA16: 0 | AB16: 0 | AC16: 0 | AD16: 0 | AE16: 0 | AF16: 0 | AG16: 0 | AH16: 0 | AI16: 0 | AJ16: 0 | AK16: 0 | AL16: 0 | AM16: 0 | AN16: 0 | AO16: 0 | AP16: 0 | AQ16: 0 | AR16: 0 | AS16: 0 | AT16: 0 | AU16: 0 | AV16: 0 | AW16: 0 | AX16: 0 | AY16: 0 | AZ16: 0
B17: PPA Contracted Generation | C17: Net Zero | D17: =IF('TECHNOLOGY REGISTER'!D18="","",'TECHNOLOGY REGISTER'!D18) -> Distribution | F17: GWh/Year | G17: 1236.2788 | H17: 1018.6953 | I17: 1381.4733 | J17: 1297.2233 | K17: 978.36189 | L17: 767.05617 | M17: 706.02834 | N17: 707.55612 | O17: 705.38945 | P17: 722.66724 | Q17: 799.66731 | R17: 676.72276 | S17: 735.47281 | T17: 720.9728 | U17: 904.13961 | V17: 381.83364 | W17: 435.72257 | X17: 494.22262 | Y17: 519.55597 | Z17: 547.63933 | AA17: 605.1116 | AB17: 660.50053 | AC17: 597.52826 | AD17: 582.63936 | AE17: 661.94497 | AF17: 648.88941 | AG17: 726.77836 | AH17: 925.36185 | AI17: 1237.2788 | AJ17: 1228.2232 | AK17: 1295.6121 | AL17: 1383.7511 | AM17: 1339.9177 | AN17: 1305.0844 | AO17: 1282.1399 | AP17: 1265.251 | AQ17: 1278.6677 | AR17: 1257.0843 | AS17: 1234.501 | AT17: 1212.3065 | AU17: 1189.3898 | AV17: 1166.4454 | AW17: 1143.5009 | AX17: 1120.5287 | AY17: 1097.5842 | AZ17: 1085.5009
... B22: PPA Contracted Generation | C22: Net Zero | D22: =IF('TECHNOLOGY REGISTER'!D23="","",'TECHNOLOGY REGISTER'!D23) -> Direct Hydro | F22: GWh/Year | G22: 4347.7627 | H22: 3433.2435 | I22: 4692.8926 | J22: 4421.8646 | K22: 3338.1971 | L22: 2625.7614 | M22: 2425.9834 | N22: 2437.9649 | O22: 2419.5205 | P22: 2409.0575 | Q22: 2671.6132 | R22: 2255.7425 | S22: 2451.576 | T22: 2403.2427 | U22: 3013.7987 | V22: 1272.7788 | W22: 1452.4086 | X22: 1647.4087 | Y22: 1731.8532 | Z22: 1825.4644 | AA22: 2017.0387 | AB22: 2201.6684 | AC22: 1991.7609 | AD22: 1942.1312 | AE22: 2206.4832 | AF22: 2162.9647 | AG22: 2422.5945 | AH22: 3084.5395 | AI22: 4124.2626 | AJ22: 4094.0773 | AK22: 4318.7072 | AL22: 4612.5037 | AM22: 4466.3925 | AN22: 4350.2813 | AO22: 4273.7997 | AP22: 4217.5034 | AQ22: 4262.2256 | AR22: 4190.2811 | AS22: 4115.0033 | AT22: 4041.0218 | AU22: 3964.6328 | AV22: 3888.1513 | AW22: 3811.6697 | AX22: 3735.0956 | AY22: 3658.614 | AZ22: 3618.3362
B23: PPA Contracted Generation | C23: Net Zero | D23: =IF('TECHNOLOGY REGISTER'!D24="","",'TECHNOLOGY REGISTER'!D24) | F23: GWh/Year
B24: PPA Contracted Generation | C24: Net Zero | D24: =IF('TECHNOLOGY REGISTER'!D25="","",'TECHNOLOGY REGISTER'!D25) | F24: GWh/Year
B25: PPA Contracted Generation | C25: Net Zero | D25: =IF('TECHNOLOGY REGISTER'!D26="","",'TECHNOLOGY REGISTER'!D26) | F25: GWh/Year
B26: PPA Contracted Generation | C26: Net Zero | D26: =IF('TECHNOLOGY REGISTER'!D27="","",'TECHNOLOGY REGISTER'!D27) | F26: GWh/Year
B27: PPA Contracted Generation | C27: Net Zero | D27: =IF('TECHNOLOGY REGISTER'!D28="","",'TECHNOLOGY REGISTER'!D28) | F27: GWh/Year
B28: PPA Contracted Generation | C28: Net Zero | D28: =IF('TECHNOLOGY REGISTER'!D29="","",'TECHNOLOGY REGISTER'!D29) | F28: GWh/Year
B29: PPA Contracted Generation | C29: Net Zero | D29: =IF('TECHNOLOGY REGISTER'!D30="","",'TECHNOLOGY REGISTER'!D30) | F29: GWh/Year
B30: PPA Contracted Generation | C30: Net Zero | D30: =IF('TECHNOLOGY REGISTER'!D31="","",'TECHNOLOGY REGISTER'!D31) | F30: GWh/Year
B31: PPA Contracted Generation | C31: Net Zero | D31: =IF('TECHNOLOGY REGISTER'!D32="","",'TECHNOLOGY REGISTER'!D32) | F31: GWh/Year
B32: PPA Contracted Generation | C32: Net Zero | D32: =IF('TECHNOLOGY REGISTER'!D33="","",'TECHNOLOGY REGISTER'!D33) | F32: GWh/Year
B33: PPA Contracted Generation | C33: Net Zero | D33: =IF('TECHNOLOGY REGISTER'!D34="","",'TECHNOLOGY REGISTER'!D34) | F33: GWh/Year
B34: PPA Contracted Generation | C34: Net Zero | D34: =IF('TECHNOLOGY REGISTER'!D35="","",'TECHNOLOGY REGISTER'!D35) | F34: GWh/Year
... B55: PPA Contracted Generation | C55: Net Zero | D55: =IF('TECHNOLOGY REGISTER'!D56="","",'TECHNOLOGY REGISTER'!D56) | F55: GWh/Year
B56: 2. Standard Off-taker Share
B57: Standard Off-taker Share | C57: Net Zero | D57: =IF('TECHNOLOGY REGISTER'!D7="","",'TECHNOLOGY REGISTER'!D7) -> Biomass | F57: % | G57: 1 | H57: 1 | I57: 1 | J57: 1 | K57: 1 | L57: 1 | M57: 1 | N57: 1 | O57: 1 | P57: 1 | Q57: 1 | R57: 1 | S57: 1 | T57: 1 | U57: 1 | V57: 1 | W57: 1 | X57: 1 | Y57: 1 | Z57: 1 | AA57: 1 | AB57: 1 | AC57: 1 | AD57: 1 | AE57: 1 | AF57: 1 | AG57: 1 | AH57: 1 | AI57: 1 | AJ57: 1 | AK57: 1 | AL57: 1 | AM57: 1 | AN57: 1 | AO57: 1 | AP57: 1 | AQ57: 1 | AR57: 1 | AS57: 1 | AT57: 1 | AU57: 1 | AV57: 1 | AW57: 1 | AX57: 1 | AY57: 1 | AZ57: 1
B58: Standard Off-taker Share | C58: Net Zero | D58: =IF('TECHNOLOGY REGISTER'!D8="","",'TECHNOLOGY REGISTER'!D8) -> Geothermal | F58: % | G58: 1 | H58: 1 | I58: 1 | J58: 1 | K58: 1 | L58: 1 | M58: 1 | N58: 1 | O58: 1 | P58: 1 | Q58: 1 | R58: 1 | S58: 1 | T58: 1 | U58: 1 | V58: 1 | W58: 1 | X58: 1 | Y58: 1 | Z58: 1 | AA58: 1 | AB58: 1 | AC58: 1 | AD58: 1 | AE58: 1 | AF58: 1 | AG58: 1 | AH58: 1 | AI58: 1 | AJ58: 1 | AK58: 1 | AL58: 1 | AM58: 1 | AN58: 1 | AO58: 1 | AP58: 1 | AQ58: 1 | AR58: 1 | AS58: 1 | AT58: 1 | AU58: 1 | AV58: 1 | AW58: 1 | AX58: 1 | AY58: 1 | AZ58: 1
B59: Standard Off-taker Share | C59: Net Zero | D59: =IF('TECHNOLOGY REGISTER'!D9="","",'TECHNOLOGY REGISTER'!D9) -> Solar PV | F59: % | G59: 1 | H59: 1 | I59: 1 | J59: 1 | K59: 1 | L59: 1 | M59: 1 | N59: 1 | O59: 1 | P59: 1 | Q59: 1 | R59: 1 | S59: 1 | T59: 1 | U59: 1 | V59: 1 | W59: 1 | X59: 1 | Y59: 1 | Z59: 1 | AA59: 1 | AB59: 1 | AC59: 1 | AD59: 1 | AE59: 1 | AF59: 1 | AG59: 1 | AH59: 1 | AI59: 1 | AJ59: 1 | AK59: 1 | AL59: 1 | AM59: 1 | AN59: 1 | AO59: 1 | AP59: 1 | AQ59: 1 | AR59: 1 | AS59: 1 | AT59: 1 | AU59: 1 | AV59: 1 | AW59: 1 | AX59: 1 | AY59: 1 | AZ59: 1
B60: Standard Off-taker Share | C60: Net Zero | D60: =IF('TECHNOLOGY REGISTER'!D10="","",'TECHNOLOGY REGISTER'!D10) -> CSP | F60: % | G60: 0.96767144 | H60: 0.9421514 | I60: 0.93126077 | J60: 0.92823706 | K60: 0.9210942 | L60: 0.8873353 | M60: 0.86304451 | N60: 0.84801359 | O60: 0.82265759 | P60: 0.7466971 | Q60: 0.72699441 | R60: 0.69563779 | S60: 0.69242346 | T60: 0.69926798 | U60: 0.69643987 | V60: 0.6440437 | W60: 0.63859642 | X60: 0.6019053 | Y60: 0.59668286 | Z60: 0.59073015 | AA60: 0.58434597 | AB60: 0.57781674 | AC60: 0.56015132 | AD60: 0.5458689 | AE60: 0.53538056 | AF60: 0.51105322 | AG60: 0.50201873 | AH60: 0.49216413 | AI60: 0.48813074 | AJ60: 0.48442807 | AK60: 0.48146044 | AL60: 0.47911589 | AM60: 0.47679163 | AN60: 0.47447196 | AO60: 0.47219465 | AP60: 0.46982305 | AQ60: 0.4677462 | AR60: 0.46550705 | AS60: 0.4633084 | AT60: 0.46112409 | AU60: 0.45897073 | AV60: 0.45683945 | AW60: 0.45472993 | AX60: 0.45263574 | AY60: 0.45056477 | AZ60: 0.44825946
B61: Standard Off-taker Share | C61: Net Zero | D61: =IF('TECHNOLOGY REGISTER'!D11="","",'TECHNOLOGY REGISTER'!D11) -> Hydropower | F61: % | G61: 1 | H61: 1 | I61: 1 | J61: 1 | K61: 1 | L61: 1 | M61: 1 | N61: 1 | O61: 1 | P61: 1 | Q61: 1 | R61: 1 | S61: 1 | T61: 1 | U61: 1 | V61: 1 | W61: 1 | X61: 1 | Y61: 1 | Z61: 1 | AA61: 1 | AB61: 1 | AC61: 1 | AD61: 1 | AE61: 1 | AF61: 1 | AG61: 1 | AH61: 1 | AI61: 1 | AJ61: 1 | AK61: 1 | AL61: 1 | AM61: 1 | AN61: 1 | AO61: 1 | AP61: 1 | AQ61: 1 | AR61: 1 | AS61: 1 | AT61: 1 | AU61: 1 | AV61: 1 | AW61: 1 | AX61: 1 | AY61: 1 | AZ61: 1
B62: Standard Off-taker Share | C62: Net Zero | D62: =IF('TECHNOLOGY REGISTER'!D12="","",'TECHNOLOGY REGISTER'!D12) -> Nuclear | F62: % | G62: 1 | H62: 1 | I62: 1 | J62: 1 | K62: 1 | L62: 1 | M62: 1 | N62: 1 | O62: 1 | P62: 1 | Q62: 1 | R62: 1 | S62: 1 | T62: 1 | U62: 1 | V62: 1 | W62: 1 | X62: 1 | Y62: 1 | Z62: 1 | AA62: 1 | AB62: 1 | AC62: 1 | AD62: 1 | AE62: 1 | AF62: 1 | AG62: 1 | AH62: 1 | AI62: 1 | AJ62: 1 | AK62: 1 | AL62: 1 | AM62: 1 | AN62: 1 | AO62: 1 | AP62: 1 | AQ62: 1 | AR62: 1 | AS62: 1 | AT62: 1 | AU62: 1 | AV62: 1 | AW62: 1 | AX62: 1 | AY62: 1 | AZ62: 1
B63: Standard Off-taker Share | C63: Net Zero | D63: =IF('TECHNOLOGY REGISTER'!D13="","",'TECHNOLOGY REGISTER'!D13) -> Wind | F63: % | G63: 1 | H63: 1 | I63: 1 | J63: 1 | K63: 1 | L63: 1 | M63: 1 | N63: 1 | O63: 1 | P63: 1 | Q63: 1 | R63: 1 | S63: 1 | T63: 1 | U63: 1 | V63: 1 | W63: 1 | X63: 1 | Y63: 1 | Z63: 1 | AA63: 1 | AB63: 1 | AC63: 1 | AD63: 1 | AE63: 1 | AF63: 1 | AG63: 1 | AH63: 1 | AI63: 1 | AJ63: 1 | AK63: 1 | AL63: 1 | AM63: 1 | AN63: 1 | AO63: 1 | AP63: 1 | AQ63: 1 | AR63: 1 | AS63: 1 | AT63: 1 | AU63: 1 | AV63: 1 | AW63: 1 | AX63: 1 | AY63: 1 | AZ63: 1
B64: Standard Off-taker Share | C64: Net Zero | D64: =IF('TECHNOLOGY REGISTER'!D14="","",'TECHNOLOGY REGISTER'!D14) -> Coal | F64: % | G64: 1 | H64: 1 | I64: 1 | J64: 1 | K64: 1 | L64: 1 | M64: 1 | N64: 1 | O64: 1 | P64: 1 | Q64: 1 | R64: 1 | S64: 1 | T64: 1 | U64: 1 | V64: 1 | W64: 1 | X64: 1 | Y64: 1 | Z64: 1 | AA64: 1 | AB64: 1 | AC64: 1 | AD64: 1 | AE64: 1 | AF64: 1 | AG64: 1 | AH64: 1 | AI64: 1 | AJ64: 1 | AK64: 1 | AL64: 1 | AM64: 1 | AN64: 1 | AO64: 1 | AP64: 1 | AQ64: 1 | AR64: 1 | AS64: 1 | AT64: 1 | AU64: 1 | AV64: 1 | AW64: 1 | AX64: 1 | AY64: 1 | AZ64: 1
B65: Standard Off-taker Share | C65: Net Zero | D65: =IF('TECHNOLOGY REGISTER'!D15="","",'TECHNOLOGY REGISTER'!D15) -> Oil | F65: % | G65: 1 | H65: 1 | I65: 1 | J65: 1 | K65: 1 | L65: 1 | M65: 1 | N65: 1 | O65: 1 | P65: 1 | Q65: 1 | R65: 1 | S65: 1 | T65: 1 | U65: 1 | V65: 1 | W65: 1 | X65: 1 | Y65: 1 | Z65: 1 | AA65: 1 | AB65: 1 | AC65: 1 | AD65: 1 | AE65: 1 | AF65: 1 | AG65: 1 | AH65: 1 | AI65: 1 | AJ65: 1 | AK65: 1 | AL65: 1 | AM65: 1 | AN65: 1 | AO65: 1 | AP65: 1 | AQ65: 1 | AR65: 1 | AS65: 1 | AT65: 1 | AU65: 1 | AV65: 1 | AW65: 1 | AX65: 1 | AY65: 1 | AZ65: 1
...

Sheet WHOLESALE REVENUE
B1: WHOLESALE REVENUE
B2: ← Return to COVER
B4: Variable | C4: Scenario | D4: Technology | E4: Currency | F4: Name | G4: Off-taker | H4: Unit | I4: 2025 | J4: 2026 | K4: 2027 | L4: 2028 | M4: 2029 | N4: 2030 | O4: 2031 | P4: 2032 | Q4: 2033 | R4: 2034 | S4: 2035 | T4: 2036 | U4: 2037 | V4: 2038 | W4: 2039 | X4: 2040 | Y4: 2041 | Z4: 2042 | AA4: 2043 | AB4: 2044 | AC4: 2045 | AD4: 2046 | AE4: 2047 | AF4: 2048 | AG4: 2049 | AH4: 2050 | AI4: 2051 | AJ4: 2052 | AK4: 2053 | AL4: 2054 | AM4: 2055 | AN4: 2056 | AO4: 2057 | AP4: 2058 | AQ4: 2059 | AR4: 2060 | AS4: 2061 | AT4: 2062 | AU4: 2063 | AV4: 2064 | AW4: 2065 | AX4: 2066 | AY4: 2067 | AZ4: 2068 | BA4: 2069 | BB4: 2070
B5: 1. Share of Off-take
B6: Share of Off-take | C6: Net Zero | D6: =IF('TECHNOLOGY REGISTER'!D7="","",'TECHNOLOGY REGISTER'!D7) -> Biomass | E6: KES | F6: 1 | G6: Transmission | H6: %
B7: Share of Off-take | C7: Net Zero | D7: =IF('TECHNOLOGY REGISTER'!D8="","",'TECHNOLOGY REGISTER'!D8) -> Geothermal | E7: KES | F7: 1 | G7: Transmission | H7: %
B8: Share of Off-take | C8: Net Zero | D8: =IF('TECHNOLOGY REGISTER'!D9="","",'TECHNOLOGY REGISTER'!D9) -> Solar PV | E8: KES | F8: 1 | G8: Transmission | H8: %
B9: Share of Off-take | C9: Net Zero | D9: =IF('TECHNOLOGY REGISTER'!D10="","",'TECHNOLOGY REGISTER'!D10) -> CSP | E9: KES | F9: 1 | G9: Transmission | H9: %
B10: Share of Off-take | C10: Net Zero | D10: =IF('TECHNOLOGY REGISTER'!D11="","",'TECHNOLOGY REGISTER'!D11) -> Hydropower | E10: KES | F10: 1 | G10: Transmission | H10: %
B11: Share of Off-take | C11: Net Zero | D11: =IF('TECHNOLOGY REGISTER'!D12="","",'TECHNOLOGY REGISTER'!D12) -> Nuclear | E11: KES | F11: 1 | G11: Transmission | H11: %
B12: Share of Off-take | C12: Net Zero | D12: =IF('TECHNOLOGY REGISTER'!D13="","",'TECHNOLOGY REGISTER'!D13) -> Wind | E12: KES | F12: 1 | G12: Transmission | H12: %
B13: Share of Off-take | C13: Net Zero | D13: =IF('TECHNOLOGY REGISTER'!D14="","",'TECHNOLOGY REGISTER'!D14) -> Coal | E13: KES | F13: 1 | G13: Transmission | H13: %
B14: Share of Off-take | C14: Net Zero | D14: =IF('TECHNOLOGY REGISTER'!D15="","",'TECHNOLOGY REGISTER'!D15) -> Oil | E14: KES | F14: 1 | G14: Distribution | H14: %
B15: Share of Off-take | C15: Net Zero | D15: =IF('TECHNOLOGY REGISTER'!D16="","",'TECHNOLOGY REGISTER'!D16) -> Gas | E15: KES | F15: Residential | G15: Direct | H15: % | I15: 0.3075341 | J15: 0.3075341 | K15: 0.3075341 | L15: 0.3075341 | M15: 0.3075341 | N15: 0.3075341 | O15: 0.3075341 | P15: 0.3075341 | Q15: 0.3075341 | R15: 0.3075341 | S15: 0.3075341 | T15: 0.3075341 | U15: 0.3075341 | V15: 0.3075341 | W15: 0.3075341 | X15: 0.3075341 | Y15: 0.3075341 | Z15: 0.3075341 | AA15: 0.3075341 | AB15: 0.3075341 | AC15: 0.3075341 | AD15: 0.3075341 | AE15: 0.3075341 | AF15: 0.3075341 | AG15: 0.3075341 | AH15: 0.3075341 | AI15: 0.3075341 | AJ15: 0.3075341 | AK15: 0.3075341 | AL15: 0.3075341 | AM15: 0.3075341 | AN15: 0.3075341 | AO15: 0.3075341 | AP15: 0.3075341 | AQ15: 0.3075341 | AR15: 0.3075341 | AS15: 0.3075341 | AT15: 0.3075341 | AU15: 0.3075341 | AV15: 0.3075341 | AW15: 0.3075341 | AX15: 0.3075341 | AY15: 0.3075341 | AZ15: 0.3075341 | BA15: 0.3075341 | BB15: 0.3075341
B16: Share of Off-take | C16: Net Zero | D16: =IF('TECHNOLOGY REGISTER'!D17="","",'TECHNOLOGY REGISTER'!D17) -> Transmission | E16: KES | F16: 1 | G16: Transmission | H16: %
B17: Share of Off-take | C17: Net Zero | D17: =IF('TECHNOLOGY REGISTER'!D18="","",'TECHNOLOGY REGISTER'!D18) -> Distribution | E17: KES | F17: 1 | G17: Transmission | H17: %
